[2024-06-02T20:20:09.618+0000] {taskinstance.py:1979} INFO - Dependencies all met for dep_context=non-requeueable deps ti=<TaskInstance: postgre_exercises.retrieve_data_iris manual__2024-06-02T20:14:04.004381+00:00 [queued]>
[2024-06-02T20:20:09.624+0000] {taskinstance.py:1979} INFO - Dependencies all met for dep_context=requeueable deps ti=<TaskInstance: postgre_exercises.retrieve_data_iris manual__2024-06-02T20:14:04.004381+00:00 [queued]>
[2024-06-02T20:20:09.624+0000] {taskinstance.py:2193} INFO - Starting attempt 3 of 4
[2024-06-02T20:20:09.633+0000] {taskinstance.py:2214} INFO - Executing <Task(PythonOperator): retrieve_data_iris> on 2024-06-02 20:14:04.004381+00:00
[2024-06-02T20:20:09.638+0000] {standard_task_runner.py:60} INFO - Started process 1774 to run task
[2024-06-02T20:20:09.641+0000] {standard_task_runner.py:87} INFO - Running: ['***', 'tasks', 'run', 'postgre_exercises', 'retrieve_data_iris', 'manual__2024-06-02T20:14:04.004381+00:00', '--job-id', '22', '--raw', '--subdir', 'DAGS_FOLDER/create_table.py', '--cfg-path', '/tmp/tmp1ng43kmg']
[2024-06-02T20:20:09.642+0000] {standard_task_runner.py:88} INFO - Job 22: Subtask retrieve_data_iris
[2024-06-02T20:20:09.673+0000] {task_command.py:423} INFO - Running <TaskInstance: postgre_exercises.retrieve_data_iris manual__2024-06-02T20:14:04.004381+00:00 [running]> on host 35a5c0dbc0eb
[2024-06-02T20:20:09.720+0000] {taskinstance.py:2510} INFO - Exporting env vars: AIRFLOW_CTX_DAG_EMAIL='msaipulrx@gmail.com' AIRFLOW_CTX_DAG_OWNER='saipul' AIRFLOW_CTX_DAG_ID='postgre_exercises' AIRFLOW_CTX_TASK_ID='retrieve_data_iris' AIRFLOW_CTX_EXECUTION_DATE='2024-06-02T20:14:04.004381+00:00' AIRFLOW_CTX_TRY_NUMBER='3' AIRFLOW_CTX_DAG_RUN_ID='manual__2024-06-02T20:14:04.004381+00:00'
[2024-06-02T20:20:09.750+0000] {taskinstance.py:2728} ERROR - Task failed with exception
Traceback (most recent call last):
  File "/home/airflow/.local/lib/python3.8/site-packages/sqlalchemy/engine/base.py", line 1910, in _execute_context
    self.dialect.do_execute(
  File "/home/airflow/.local/lib/python3.8/site-packages/sqlalchemy/engine/default.py", line 736, in do_execute
    cursor.execute(statement, parameters)
psycopg2.errors.UndefinedColumn: column iris.id does not exist
LINE 2:      SELECT iris.Id, iris.SepalLengthCm, iris.SepalWidthCm, ...
                    ^
HINT:  Perhaps you meant to reference the column "iris.Id".


The above exception was the direct cause of the following exception:

Traceback (most recent call last):
  File "/home/airflow/.local/lib/python3.8/site-packages/airflow/models/taskinstance.py", line 444, in _execute_task
    result = _execute_callable(context=context, **execute_callable_kwargs)
  File "/home/airflow/.local/lib/python3.8/site-packages/airflow/models/taskinstance.py", line 414, in _execute_callable
    return execute_callable(context=context, **execute_callable_kwargs)
  File "/home/airflow/.local/lib/python3.8/site-packages/airflow/operators/python.py", line 200, in execute
    return_value = self.execute_callable()
  File "/home/airflow/.local/lib/python3.8/site-packages/airflow/operators/python.py", line 217, in execute_callable
    return self.python_callable(*self.op_args, **self.op_kwargs)
  File "/opt/airflow/dags/script/call_model.py", line 35, in read_data_iris
    read_data_df = pd.read_sql(sql,con_db)
  File "/home/airflow/.local/lib/python3.8/site-packages/pandas/io/sql.py", line 663, in read_sql
    return pandas_sql.read_query(
  File "/home/airflow/.local/lib/python3.8/site-packages/pandas/io/sql.py", line 1738, in read_query
    result = self.execute(sql, params)
  File "/home/airflow/.local/lib/python3.8/site-packages/pandas/io/sql.py", line 1562, in execute
    return self.con.exec_driver_sql(sql, *args)
  File "/home/airflow/.local/lib/python3.8/site-packages/sqlalchemy/engine/base.py", line 1770, in exec_driver_sql
    return self._exec_driver_sql(
  File "/home/airflow/.local/lib/python3.8/site-packages/sqlalchemy/engine/base.py", line 1674, in _exec_driver_sql
    ret = self._execute_context(
  File "/home/airflow/.local/lib/python3.8/site-packages/sqlalchemy/engine/base.py", line 1953, in _execute_context
    self._handle_dbapi_exception(
  File "/home/airflow/.local/lib/python3.8/site-packages/sqlalchemy/engine/base.py", line 2134, in _handle_dbapi_exception
    util.raise_(
  File "/home/airflow/.local/lib/python3.8/site-packages/sqlalchemy/util/compat.py", line 211, in raise_
    raise exception
  File "/home/airflow/.local/lib/python3.8/site-packages/sqlalchemy/engine/base.py", line 1910, in _execute_context
    self.dialect.do_execute(
  File "/home/airflow/.local/lib/python3.8/site-packages/sqlalchemy/engine/default.py", line 736, in do_execute
    cursor.execute(statement, parameters)
sqlalchemy.exc.ProgrammingError: (psycopg2.errors.UndefinedColumn) column iris.id does not exist
LINE 2:      SELECT iris.Id, iris.SepalLengthCm, iris.SepalWidthCm, ...
                    ^
HINT:  Perhaps you meant to reference the column "iris.Id".

[SQL: 
     SELECT iris.Id, iris.SepalLengthCm, iris.SepalWidthCm, iris.PetalLengthCm, iris.PetalWidthCm FROM iris
     ]
(Background on this error at: https://sqlalche.me/e/14/f405)
[2024-06-02T20:20:09.757+0000] {taskinstance.py:1149} INFO - Marking task as UP_FOR_RETRY. dag_id=postgre_exercises, task_id=retrieve_data_iris, execution_date=20240602T201404, start_date=20240602T202009, end_date=20240602T202009
[2024-06-02T20:20:09.764+0000] {standard_task_runner.py:107} ERROR - Failed to execute job 22 for task retrieve_data_iris ((psycopg2.errors.UndefinedColumn) column iris.id does not exist
LINE 2:      SELECT iris.Id, iris.SepalLengthCm, iris.SepalWidthCm, ...
                    ^
HINT:  Perhaps you meant to reference the column "iris.Id".

[SQL: 
     SELECT iris.Id, iris.SepalLengthCm, iris.SepalWidthCm, iris.PetalLengthCm, iris.PetalWidthCm FROM iris
     ]
(Background on this error at: https://sqlalche.me/e/14/f405); 1774)
[2024-06-02T20:20:09.781+0000] {local_task_job_runner.py:234} INFO - Task exited with return code 1
[2024-06-02T20:20:09.791+0000] {taskinstance.py:3309} INFO - 0 downstream tasks scheduled from follow-on schedule check
