[2024-06-02T18:32:02.467+0000] {taskinstance.py:1979} INFO - Dependencies all met for dep_context=non-requeueable deps ti=<TaskInstance: postgre_exercises.createTable scheduled__2020-11-28T00:00:00+00:00 [queued]>
[2024-06-02T18:32:02.470+0000] {taskinstance.py:1979} INFO - Dependencies all met for dep_context=requeueable deps ti=<TaskInstance: postgre_exercises.createTable scheduled__2020-11-28T00:00:00+00:00 [queued]>
[2024-06-02T18:32:02.471+0000] {taskinstance.py:2193} INFO - Starting attempt 1 of 2
[2024-06-02T18:32:02.480+0000] {taskinstance.py:2214} INFO - Executing <Task(PostgresOperator): createTable> on 2020-11-28 00:00:00+00:00
[2024-06-02T18:32:02.484+0000] {standard_task_runner.py:60} INFO - Started process 92 to run task
[2024-06-02T18:32:02.488+0000] {standard_task_runner.py:87} INFO - Running: ['***', 'tasks', 'run', 'postgre_exercises', 'createTable', 'scheduled__2020-11-28T00:00:00+00:00', '--job-id', '11', '--raw', '--subdir', 'DAGS_FOLDER/create_table.py', '--cfg-path', '/tmp/tmp0ty3apmy']
[2024-06-02T18:32:02.491+0000] {standard_task_runner.py:88} INFO - Job 11: Subtask createTable
[2024-06-02T18:32:02.550+0000] {task_command.py:423} INFO - Running <TaskInstance: postgre_exercises.createTable scheduled__2020-11-28T00:00:00+00:00 [running]> on host 35a5c0dbc0eb
[2024-06-02T18:32:02.607+0000] {taskinstance.py:2510} INFO - Exporting env vars: AIRFLOW_CTX_DAG_EMAIL='msaipulrx@gmail.com' AIRFLOW_CTX_DAG_OWNER='saipul' AIRFLOW_CTX_DAG_ID='postgre_exercises' AIRFLOW_CTX_TASK_ID='createTable' AIRFLOW_CTX_EXECUTION_DATE='2020-11-28T00:00:00+00:00' AIRFLOW_CTX_TRY_NUMBER='1' AIRFLOW_CTX_DAG_RUN_ID='scheduled__2020-11-28T00:00:00+00:00'
[2024-06-02T18:32:02.609+0000] {sql.py:276} INFO - Executing: /* CREATE_TABLE_my_table.sql */
CREATE TABLE IF NOT EXISTS iris (
    Id int NOT NULL , 
    sepallengthcm DECIMAL(5,2) NOT NULL, 
    sepalwidthcm DECIMAL(5,2) NOT NULL, 
    petallengthcm DECIMAL(5,2) NOT NULL,
    petalwidthcm DECIMAL(5,2) NOT NULL,
    species VARCHAR(50),
    PRIMARY KEY (Id));
[2024-06-02T18:32:02.617+0000] {base.py:83} INFO - Using connection ID 'postgres_conn' for task execution.
[2024-06-02T18:32:02.623+0000] {base.py:83} INFO - Using connection ID 'postgres_conn' for task execution.
[2024-06-02T18:32:02.624+0000] {taskinstance.py:2728} ERROR - Task failed with exception
Traceback (most recent call last):
  File "/home/airflow/.local/lib/python3.8/site-packages/airflow/models/taskinstance.py", line 444, in _execute_task
    result = _execute_callable(context=context, **execute_callable_kwargs)
  File "/home/airflow/.local/lib/python3.8/site-packages/airflow/models/taskinstance.py", line 414, in _execute_callable
    return execute_callable(context=context, **execute_callable_kwargs)
  File "/home/airflow/.local/lib/python3.8/site-packages/airflow/providers/common/sql/operators/sql.py", line 282, in execute
    output = hook.run(
  File "/home/airflow/.local/lib/python3.8/site-packages/airflow/providers/common/sql/hooks/sql.py", line 397, in run
    with closing(self.get_conn()) as conn:
  File "/home/airflow/.local/lib/python3.8/site-packages/airflow/providers/postgres/hooks/postgres.py", line 161, in get_conn
    self.conn = psycopg2.connect(**conn_args)
  File "/home/airflow/.local/lib/python3.8/site-packages/psycopg2/__init__.py", line 122, in connect
    conn = _connect(dsn, connection_factory=connection_factory, **kwasync)
psycopg2.OperationalError: connection to server at "localhost" (127.0.0.1), port 5435 failed: Connection refused
	Is the server running on that host and accepting TCP/IP connections?
connection to server at "localhost" (::1), port 5435 failed: Cannot assign requested address
	Is the server running on that host and accepting TCP/IP connections?

[2024-06-02T18:32:02.631+0000] {taskinstance.py:1149} INFO - Marking task as UP_FOR_RETRY. dag_id=postgre_exercises, task_id=createTable, execution_date=20201128T000000, start_date=20240602T183202, end_date=20240602T183202
[2024-06-02T18:32:02.645+0000] {standard_task_runner.py:107} ERROR - Failed to execute job 11 for task createTable (connection to server at "localhost" (127.0.0.1), port 5435 failed: Connection refused
	Is the server running on that host and accepting TCP/IP connections?
connection to server at "localhost" (::1), port 5435 failed: Cannot assign requested address
	Is the server running on that host and accepting TCP/IP connections?
; 92)
[2024-06-02T18:32:02.672+0000] {local_task_job_runner.py:234} INFO - Task exited with return code 1
[2024-06-02T18:32:02.680+0000] {warnings.py:109} WARNING - /home/***/.local/lib/python3.8/site-packages/***/models/baseoperator.py:1201: AirflowProviderDeprecationWarning: Call to deprecated class PostgresOperator. (Please use `***.providers.common.sql.operators.sql.SQLExecuteQueryOperator`.Also, you can provide `hook_params={'schema': <database>}`.)
  result = cls.__new__(cls)

[2024-06-02T18:32:02.689+0000] {taskinstance.py:3309} INFO - 0 downstream tasks scheduled from follow-on schedule check
